<?xml version="1.0" encoding="UTF-8"?>
<!-- Generated by org.testng.reporters.JUnitXMLReporter -->
<testsuite hostname="EPBYMINW3743" ignored="0" name="Default test" tests="38" failures="5" timestamp="05 Apr 2017 08:08:01 GMT" time="10.329" errors="0">
  <testcase name="TestDivByZero" time="0.005" classname="com.epam.tat.unittest.tests.CalculatorTest">
    <failure type="org.testng.TestException" message="
Method CalculatorTest.TestDivByZero(double, double)[pri:0, instance:com.epam.tat.unittest.tests.CalculatorTest@5dfcfece] should have thrown an exception of type class java.lang.NumberFormatException">
      <![CDATA[org.testng.TestException: 
Method CalculatorTest.TestDivByZero(double, double)[pri:0, instance:com.epam.tat.unittest.tests.CalculatorTest@5dfcfece] should have thrown an exception of type class java.lang.NumberFormatException
	at org.testng.internal.ExpectedExceptionsHolder.noException(ExpectedExceptionsHolder.java:89)
	at org.testng.internal.Invoker.handleInvocationResults(Invoker.java:1401)
	at org.testng.internal.Invoker.invokeMethod(Invoker.java:684)
	at org.testng.internal.Invoker.invokeTestMethod(Invoker.java:851)
	at org.testng.internal.Invoker.invokeTestMethods(Invoker.java:1177)
	at org.testng.internal.TestMethodWorker.invokeTestMethods(TestMethodWorker.java:129)
	at org.testng.internal.TestMethodWorker.run(TestMethodWorker.java:112)
	at org.testng.TestRunner.privateRun(TestRunner.java:756)
	at org.testng.TestRunner.run(TestRunner.java:610)
	at org.testng.SuiteRunner.runTest(SuiteRunner.java:387)
	at org.testng.SuiteRunner.runSequentially(SuiteRunner.java:382)
	at org.testng.SuiteRunner.privateRun(SuiteRunner.java:340)
	at org.testng.SuiteRunner.run(SuiteRunner.java:289)
	at org.testng.SuiteRunnerWorker.runSuite(SuiteRunnerWorker.java:52)
	at org.testng.SuiteRunnerWorker.run(SuiteRunnerWorker.java:86)
	at org.testng.TestNG.runSuitesSequentially(TestNG.java:1293)
	at org.testng.TestNG.runSuitesLocally(TestNG.java:1218)
	at org.testng.TestNG.runSuites(TestNG.java:1133)
	at org.testng.TestNG.run(TestNG.java:1104)
	at org.testng.remote.AbstractRemoteTestNG.run(AbstractRemoteTestNG.java:132)
	at org.testng.remote.RemoteTestNG.initAndRun(RemoteTestNG.java:236)
	at org.testng.remote.RemoteTestNG.main(RemoteTestNG.java:81)
]]>
    </failure>
  </testcase> <!-- TestDivByZero -->
  <testcase name="TestDivByZero" time="0.002" classname="com.epam.tat.unittest.tests.CalculatorTest">
    <failure type="org.testng.TestException" message="
Method CalculatorTest.TestDivByZero(double, double)[pri:0, instance:com.epam.tat.unittest.tests.CalculatorTest@5dfcfece] should have thrown an exception of type class java.lang.NumberFormatException">
      <![CDATA[org.testng.TestException: 
Method CalculatorTest.TestDivByZero(double, double)[pri:0, instance:com.epam.tat.unittest.tests.CalculatorTest@5dfcfece] should have thrown an exception of type class java.lang.NumberFormatException
	at org.testng.internal.ExpectedExceptionsHolder.noException(ExpectedExceptionsHolder.java:89)
	at org.testng.internal.Invoker.handleInvocationResults(Invoker.java:1401)
	at org.testng.internal.Invoker.invokeMethod(Invoker.java:684)
	at org.testng.internal.Invoker.invokeTestMethod(Invoker.java:851)
	at org.testng.internal.Invoker.invokeTestMethods(Invoker.java:1177)
	at org.testng.internal.TestMethodWorker.invokeTestMethods(TestMethodWorker.java:129)
	at org.testng.internal.TestMethodWorker.run(TestMethodWorker.java:112)
	at org.testng.TestRunner.privateRun(TestRunner.java:756)
	at org.testng.TestRunner.run(TestRunner.java:610)
	at org.testng.SuiteRunner.runTest(SuiteRunner.java:387)
	at org.testng.SuiteRunner.runSequentially(SuiteRunner.java:382)
	at org.testng.SuiteRunner.privateRun(SuiteRunner.java:340)
	at org.testng.SuiteRunner.run(SuiteRunner.java:289)
	at org.testng.SuiteRunnerWorker.runSuite(SuiteRunnerWorker.java:52)
	at org.testng.SuiteRunnerWorker.run(SuiteRunnerWorker.java:86)
	at org.testng.TestNG.runSuitesSequentially(TestNG.java:1293)
	at org.testng.TestNG.runSuitesLocally(TestNG.java:1218)
	at org.testng.TestNG.runSuites(TestNG.java:1133)
	at org.testng.TestNG.run(TestNG.java:1104)
	at org.testng.remote.AbstractRemoteTestNG.run(AbstractRemoteTestNG.java:132)
	at org.testng.remote.RemoteTestNG.initAndRun(RemoteTestNG.java:236)
	at org.testng.remote.RemoteTestNG.main(RemoteTestNG.java:81)
]]>
    </failure>
  </testcase> <!-- TestDivByZero -->
  <testcase name="TestDivByZero" time="0.001" classname="com.epam.tat.unittest.tests.CalculatorTest">
    <failure type="org.testng.TestException" message="
Method CalculatorTest.TestDivByZero(double, double)[pri:0, instance:com.epam.tat.unittest.tests.CalculatorTest@5dfcfece] should have thrown an exception of type class java.lang.NumberFormatException">
      <![CDATA[org.testng.TestException: 
Method CalculatorTest.TestDivByZero(double, double)[pri:0, instance:com.epam.tat.unittest.tests.CalculatorTest@5dfcfece] should have thrown an exception of type class java.lang.NumberFormatException
	at org.testng.internal.ExpectedExceptionsHolder.noException(ExpectedExceptionsHolder.java:89)
	at org.testng.internal.Invoker.handleInvocationResults(Invoker.java:1401)
	at org.testng.internal.Invoker.invokeMethod(Invoker.java:684)
	at org.testng.internal.Invoker.invokeTestMethod(Invoker.java:851)
	at org.testng.internal.Invoker.invokeTestMethods(Invoker.java:1177)
	at org.testng.internal.TestMethodWorker.invokeTestMethods(TestMethodWorker.java:129)
	at org.testng.internal.TestMethodWorker.run(TestMethodWorker.java:112)
	at org.testng.TestRunner.privateRun(TestRunner.java:756)
	at org.testng.TestRunner.run(TestRunner.java:610)
	at org.testng.SuiteRunner.runTest(SuiteRunner.java:387)
	at org.testng.SuiteRunner.runSequentially(SuiteRunner.java:382)
	at org.testng.SuiteRunner.privateRun(SuiteRunner.java:340)
	at org.testng.SuiteRunner.run(SuiteRunner.java:289)
	at org.testng.SuiteRunnerWorker.runSuite(SuiteRunnerWorker.java:52)
	at org.testng.SuiteRunnerWorker.run(SuiteRunnerWorker.java:86)
	at org.testng.TestNG.runSuitesSequentially(TestNG.java:1293)
	at org.testng.TestNG.runSuitesLocally(TestNG.java:1218)
	at org.testng.TestNG.runSuites(TestNG.java:1133)
	at org.testng.TestNG.run(TestNG.java:1104)
	at org.testng.remote.AbstractRemoteTestNG.run(AbstractRemoteTestNG.java:132)
	at org.testng.remote.RemoteTestNG.initAndRun(RemoteTestNG.java:236)
	at org.testng.remote.RemoteTestNG.main(RemoteTestNG.java:81)
]]>
    </failure>
  </testcase> <!-- TestDivByZero -->
  <testcase name="TestDivByZeroLong" time="0.002" classname="com.epam.tat.unittest.tests.CalculatorTest"/>
  <testcase name="TestDivByZeroLong" time="0.001" classname="com.epam.tat.unittest.tests.CalculatorTest"/>
  <testcase name="TestDivByZeroLong" time="0.003" classname="com.epam.tat.unittest.tests.CalculatorTest"/>
  <testcase name="testDivMethod" time="0.003" classname="com.epam.tat.unittest.tests.CalculatorTest"/>
  <testcase name="testDivMethod" time="0.001" classname="com.epam.tat.unittest.tests.CalculatorTest"/>
  <testcase name="testDivMethod" time="0.001" classname="com.epam.tat.unittest.tests.CalculatorTest"/>
  <testcase name="testDivMethod" time="0.003" classname="com.epam.tat.unittest.tests.CalculatorTest">
    <failure type="java.lang.AssertionError" message="Invalid result of the operation, correct result: 0.0 expected [true] but found [false]">
      <![CDATA[java.lang.AssertionError: Invalid result of the operation, correct result: 0.0 expected [true] but found [false]
	at org.testng.Assert.fail(Assert.java:94)
	at org.testng.Assert.failNotEquals(Assert.java:513)
	at org.testng.Assert.assertTrue(Assert.java:42)
	at com.epam.tat.unittest.tests.CalculatorTest.testDivMethod(CalculatorTest.java:37)
	at sun.reflect.NativeMethodAccessorImpl.invoke0(Native Method)
	at sun.reflect.NativeMethodAccessorImpl.invoke(Unknown Source)
	at sun.reflect.DelegatingMethodAccessorImpl.invoke(Unknown Source)
	at java.lang.reflect.Method.invoke(Unknown Source)
	at org.testng.internal.MethodInvocationHelper.invokeMethod(MethodInvocationHelper.java:104)
	at org.testng.internal.Invoker.invokeMethod(Invoker.java:645)
	at org.testng.internal.Invoker.invokeTestMethod(Invoker.java:851)
	at org.testng.internal.Invoker.invokeTestMethods(Invoker.java:1177)
	at org.testng.internal.TestMethodWorker.invokeTestMethods(TestMethodWorker.java:129)
	at org.testng.internal.TestMethodWorker.run(TestMethodWorker.java:112)
	at org.testng.TestRunner.privateRun(TestRunner.java:756)
	at org.testng.TestRunner.run(TestRunner.java:610)
	at org.testng.SuiteRunner.runTest(SuiteRunner.java:387)
	at org.testng.SuiteRunner.runSequentially(SuiteRunner.java:382)
	at org.testng.SuiteRunner.privateRun(SuiteRunner.java:340)
	at org.testng.SuiteRunner.run(SuiteRunner.java:289)
	at org.testng.SuiteRunnerWorker.runSuite(SuiteRunnerWorker.java:52)
	at org.testng.SuiteRunnerWorker.run(SuiteRunnerWorker.java:86)
	at org.testng.TestNG.runSuitesSequentially(TestNG.java:1293)
	at org.testng.TestNG.runSuitesLocally(TestNG.java:1218)
	at org.testng.TestNG.runSuites(TestNG.java:1133)
	at org.testng.TestNG.run(TestNG.java:1104)
	at org.testng.remote.AbstractRemoteTestNG.run(AbstractRemoteTestNG.java:132)
	at org.testng.remote.RemoteTestNG.initAndRun(RemoteTestNG.java:236)
	at org.testng.remote.RemoteTestNG.main(RemoteTestNG.java:81)
]]>
    </failure>
  </testcase> <!-- testDivMethod -->
  <testcase name="testIsNegativeMethod" time="0.001" classname="com.epam.tat.unittest.tests.CalculatorTest"/>
  <testcase name="testIsNegativeMethod" time="0.001" classname="com.epam.tat.unittest.tests.CalculatorTest"/>
  <testcase name="testIsNegativeMethod" time="0.001" classname="com.epam.tat.unittest.tests.CalculatorTest"/>
  <testcase name="testIsNegativeMethodNeg" time="0.001" classname="com.epam.tat.unittest.tests.CalculatorTest"/>
  <testcase name="testIsNegativeMethodNeg" time="0.002" classname="com.epam.tat.unittest.tests.CalculatorTest"/>
  <testcase name="testIsNegativeMethodNeg" time="0.002" classname="com.epam.tat.unittest.tests.CalculatorTest"/>
  <testcase name="testIsNegativeMethodNeg" time="0.001" classname="com.epam.tat.unittest.tests.CalculatorTest"/>
  <testcase name="testIsPositiveMethod" time="0.001" classname="com.epam.tat.unittest.tests.CalculatorTest"/>
  <testcase name="testIsPositiveMethod" time="0.001" classname="com.epam.tat.unittest.tests.CalculatorTest"/>
  <testcase name="testIsPositiveMethod" time="0.002" classname="com.epam.tat.unittest.tests.CalculatorTest"/>
  <testcase name="testIsPositiveMethodNeg" time="0.002" classname="com.epam.tat.unittest.tests.CalculatorTest"/>
  <testcase name="testIsPositiveMethodNeg" time="0.001" classname="com.epam.tat.unittest.tests.CalculatorTest"/>
  <testcase name="testIsPositiveMethodNeg" time="0.001" classname="com.epam.tat.unittest.tests.CalculatorTest"/>
  <testcase name="testIsPositiveMethodNeg" time="0.001" classname="com.epam.tat.unittest.tests.CalculatorTest"/>
  <testcase name="testMultMethod" time="0.007" classname="com.epam.tat.unittest.tests.CalculatorTest"/>
  <testcase name="testMultMethod" time="0.002" classname="com.epam.tat.unittest.tests.CalculatorTest"/>
  <testcase name="testMultMethod" time="0.001" classname="com.epam.tat.unittest.tests.CalculatorTest"/>
  <testcase name="testMultMethod" time="0.001" classname="com.epam.tat.unittest.tests.CalculatorTest"/>
  <testcase name="testMultMethod" time="0.001" classname="com.epam.tat.unittest.tests.CalculatorTest">
    <failure type="java.lang.AssertionError" message="Invalid result of the operation, correct result: 0.0 expected [0.0] but found [-0.0]">
      <![CDATA[java.lang.AssertionError: Invalid result of the operation, correct result: 0.0 expected [0.0] but found [-0.0]
	at org.testng.Assert.fail(Assert.java:94)
	at org.testng.Assert.failNotEquals(Assert.java:513)
	at org.testng.Assert.assertEqualsImpl(Assert.java:135)
	at org.testng.Assert.assertEquals(Assert.java:116)
	at com.epam.tat.unittest.tests.CalculatorTest.testMultMethod(CalculatorTest.java:28)
	at sun.reflect.NativeMethodAccessorImpl.invoke0(Native Method)
	at sun.reflect.NativeMethodAccessorImpl.invoke(Unknown Source)
	at sun.reflect.DelegatingMethodAccessorImpl.invoke(Unknown Source)
	at java.lang.reflect.Method.invoke(Unknown Source)
	at org.testng.internal.MethodInvocationHelper.invokeMethod(MethodInvocationHelper.java:104)
	at org.testng.internal.Invoker.invokeMethod(Invoker.java:645)
	at org.testng.internal.Invoker.invokeTestMethod(Invoker.java:851)
	at org.testng.internal.Invoker.invokeTestMethods(Invoker.java:1177)
	at org.testng.internal.TestMethodWorker.invokeTestMethods(TestMethodWorker.java:129)
	at org.testng.internal.TestMethodWorker.run(TestMethodWorker.java:112)
	at org.testng.TestRunner.privateRun(TestRunner.java:756)
	at org.testng.TestRunner.run(TestRunner.java:610)
	at org.testng.SuiteRunner.runTest(SuiteRunner.java:387)
	at org.testng.SuiteRunner.runSequentially(SuiteRunner.java:382)
	at org.testng.SuiteRunner.privateRun(SuiteRunner.java:340)
	at org.testng.SuiteRunner.run(SuiteRunner.java:289)
	at org.testng.SuiteRunnerWorker.runSuite(SuiteRunnerWorker.java:52)
	at org.testng.SuiteRunnerWorker.run(SuiteRunnerWorker.java:86)
	at org.testng.TestNG.runSuitesSequentially(TestNG.java:1293)
	at org.testng.TestNG.runSuitesLocally(TestNG.java:1218)
	at org.testng.TestNG.runSuites(TestNG.java:1133)
	at org.testng.TestNG.run(TestNG.java:1104)
	at org.testng.remote.AbstractRemoteTestNG.run(AbstractRemoteTestNG.java:132)
	at org.testng.remote.RemoteTestNG.initAndRun(RemoteTestNG.java:236)
	at org.testng.remote.RemoteTestNG.main(RemoteTestNG.java:81)
]]>
    </failure>
  </testcase> <!-- testMultMethod -->
  <testcase name="testParallel" time="2.007" classname="com.epam.tat.unittest.tests.CalculatorTest"/>
  <testcase name="testParallel1" time="2.002" classname="com.epam.tat.unittest.tests.CalculatorTest"/>
  <testcase name="testParallel2" time="2.003" classname="com.epam.tat.unittest.tests.CalculatorTest"/>
  <testcase name="testParallel3" time="2.002" classname="com.epam.tat.unittest.tests.CalculatorTest"/>
  <testcase name="testParallel4" time="2.002" classname="com.epam.tat.unittest.tests.CalculatorTest"/>
  <testcase name="testSumMethod" time="0.001" classname="com.epam.tat.unittest.tests.CalculatorTest"/>
  <testcase name="testSumMethod" time="0.001" classname="com.epam.tat.unittest.tests.CalculatorTest"/>
  <testcase name="testSumMethod" time="0.001" classname="com.epam.tat.unittest.tests.CalculatorTest"/>
  <testcase name="testSumMethod" time="0.001" classname="com.epam.tat.unittest.tests.CalculatorTest"/>
</testsuite> <!-- Default test -->
